<?xml version="1.0" encoding="utf-8"?>
<!-- =================================================================================== -->
<!-- |    This document was autogenerated by xacro from sample_hexapod_robot.urdf      | -->
<!-- |    EDITING THIS FILE BY HAND IS NOT RECOMMENDED                                 | -->
<!-- =================================================================================== -->
<!-- This URDF was automatically created by SolidWorks to URDF Exporter! Originally created by Stephen Brawner (brawner@gmail.com)
     Commit Version: 1.5.1-0-g916b5db  Build Version: 1.5.7152.31018
     For more information, please see http://wiki.ros.org/sw_urdf_exporter -->
<robot name="sample_hexapod_robot">
  <link name="base_link">
    <inertial>
      <origin rpy="0 0 0" xyz="-0.0201724295551156 -0.0157441046135445 -0.00674889408254364"/>
      <mass
        value="0.0716155283270815" />
      <inertia ixx="1e-6" ixy="0" ixz="0" iyy="1e-6" iyz="0" izz="1e-6"/>
    </inertial>
    <visual>
      <origin rpy="0 0 0" xyz="0 0 0"/>
      <geometry>
        <mesh filename="package://sample_hexapod_robot/meshes/base_link.STL"/>
      </geometry>
      <material name="">
        <color rgba="0.792156862745098 0.819607843137255 0.933333333333333 1"/>
      </material>
    </visual>
    <collision>
      <origin rpy="0 0 0" xyz="0 0 0"/>
      <geometry>
        <mesh filename="package://sample_hexapod_robot/meshes/base_link.STL"/>
      </geometry>
    </collision>
  </link>
  <link name="RightFrontLink1">
    <inertial>
      <origin rpy="0 0 0" xyz="-2.77555756156289E-17 0.0117444424090268 -0.00583560923500802"/>
      <mass value="0.00481299409312765"/>
      <inertia ixx="1e-6" ixy="0" ixz="0" iyy="1e-6" iyz="0" izz="1e-6"/>
    </inertial>
    <visual>
      <origin rpy="0 0 0" xyz="0 0 0"/>
      <geometry>
        <mesh filename="package://sample_hexapod_robot/meshes/RightFrontLink1.STL"/>
      </geometry>
      <material name="">
        <color rgba="0.752941176470588 0.752941176470588 0.752941176470588 1"/>
      </material>
    </visual>
    <collision>
      <origin rpy="0 0 0" xyz="0 0 0"/>
      <geometry>
        <mesh filename="package://sample_hexapod_robot/meshes/RightFrontLink1.STL"/>
      </geometry>
    </collision>
  </link>
  <joint name="RightFrontJoint1" type="fixed">
    <origin rpy="3.14159265358979 1.5707963267949 0" xyz="0.0797966933644301 -0.0194131059174563 -0.0399893477490188"/>
    <parent link="base_link"/>
    <child link="RightFrontLink1"/>
    <axis xyz="0 0 0"/>
  </joint>
  <link name="RightFrontLink2">
    <inertial>
      <origin rpy="0 0 0" xyz="0.00452867992289666 0.0139710440348122 -0.00560326484439639"/>
      <mass value="0.0532163858371582"/>
      <inertia ixx="1e-6" ixy="0" ixz="0" iyy="1e-6" iyz="0" izz="1e-6"/>
    </inertial>
    <visual>
      <origin rpy="0 0 0" xyz="0 0 0"/>
      <geometry>
        <mesh filename="package://sample_hexapod_robot/meshes/RightFrontLink2.STL"/>
      </geometry>
      <material name="">
        <color rgba="1 1 1 1"/>
      </material>
    </visual>
    <collision>
      <origin rpy="0 0 0" xyz="0 0 0"/>
      <geometry>
        <mesh filename="package://sample_hexapod_robot/meshes/RightFrontLink2.STL"/>
      </geometry>
    </collision>
  </link>
  <joint name="RightFrontJoint2" type="continuous">
    <origin rpy="-1.5707963267949 -0.786246680506596 1.5707963267949" xyz="0 0.0270001999999999 -0.0186562999999996"/>
    <parent link="RightFrontLink1"/>
    <child link="RightFrontLink2"/>
    <axis xyz="0 0 1"/>
    <dynamics damping="0.01"/>
  </joint>
  <link name="RightFrontLink3">
    <inertial>
      <origin rpy="0 0 0" xyz="0.0404128398424304 0.00597660677483936 0.00369375749998602"/>
      <mass value="0.0123870986027426"/>
      <inertia ixx="1e-6" ixy="0" ixz="0" iyy="1e-6" iyz="0" izz="1e-6"/>
    </inertial>
    <visual>
      <origin rpy="0 0 0" xyz="0 0 0"/>
      <geometry>
        <mesh filename="package://sample_hexapod_robot/meshes/RightFrontLink3.STL"/>
      </geometry>
      <material name="">
        <color rgba="0.698039215686274 0.698039215686274 0.698039215686274 1"/>
      </material>
    </visual>
    <collision>
      <origin rpy="0 0 0" xyz="0 0 0"/>
      <geometry>
        <mesh filename="package://sample_hexapod_robot/meshes/RightFrontLink3.STL"/>
      </geometry>
    </collision>
  </link>
  <joint name="RightFrontJoint3" type="continuous">
    <origin rpy="3.14159265358979 -0.785398163397442 1.5707963267949" xyz="0 0.0284480000000001 -0.019127099952002"/>
    <parent link="RightFrontLink2"/>
    <child link="RightFrontLink3"/>
    <axis xyz="0 1 0"/>
    <dynamics damping="0.01"/>
  </joint>
  <link name="RightFrontLink4">
    <inertial>
      <origin rpy="0 0 0" xyz="0.017502224050596 0.00213695685860105 4.7020139145551E-05"/>
      <mass value="0.0328903409487069"/>
      <inertia ixx="1e-6" ixy="0" ixz="0" iyy="1e-6" iyz="0" izz="1e-6"/>
    </inertial>
    <visual>
      <origin rpy="0 0 0" xyz="0 0 0"/>
      <geometry>
        <mesh filename="package://sample_hexapod_robot/meshes/RightFrontLink4.STL"/>
      </geometry>
      <material name="">
        <color rgba="1 1 1 1"/>
      </material>
    </visual>
    <collision>
      <origin rpy="0 0 0" xyz="0 0 0"/>
      <geometry>
        <mesh filename="package://sample_hexapod_robot/meshes/RightFrontLink4.STL"/>
      </geometry>
    </collision>
  </link>
  <joint name="RightFrontJoint4" type="continuous">
    <origin rpy="1.5707963267949 -0.785398163397455 3.14159265358979" xyz="0.0730630999999997 0 0.0186563000000001"/>
    <parent link="RightFrontLink3"/>
    <child link="RightFrontLink4"/>
    <axis xyz="0 0 1"/>
    <dynamics damping="0.01"/>
  </joint>
  <link name="LeftFrontLink1">
    <inertial>
      <origin rpy="0 0 0" xyz="-6.93889390390723E-18 0.0117444424090268 -0.00583560923500803"/>
      <mass value="0.00481299409312765"/>
      <inertia ixx="1e-6" ixy="0" ixz="0" iyy="1e-6" iyz="0" izz="1e-6"/>
    </inertial>
    <visual>
      <origin rpy="0 0 0" xyz="0 0 0"/>
      <geometry>
        <mesh filename="package://sample_hexapod_robot/meshes/LeftFrontLink1.STL"/>
      </geometry>
      <material name="">
        <color rgba="0.752941176470588 0.752941176470588 0.752941176470588 1"/>
      </material>
    </visual>
    <collision>
      <origin rpy="0 0 0" xyz="0 0 0"/>
      <geometry>
        <mesh filename="package://sample_hexapod_robot/meshes/LeftFrontLink1.STL"/>
      </geometry>
    </collision>
  </link>
  <joint name="LeftFrontJoint1" type="fixed">
    <origin rpy="0 -1.5707963267949 0" xyz="0.0797966933644301 0.0329108940825437 -0.0399893477490188"/>
    <parent link="base_link"/>
    <child link="LeftFrontLink1"/>
    <axis xyz="0 0 0"/>
  </joint>
  <link name="LeftFrontLInk2">
    <inertial>
      <origin rpy="0 0 0" xyz="0.0042927116829299 -0.0142494000000003 -0.00590628826906783"/>
      <mass value="0.0522696869799878"/>
      <inertia ixx="1e-6" ixy="0" ixz="0" iyy="1e-6" iyz="0" izz="1e-6"/>
    </inertial>
    <visual>
      <origin rpy="0 0 0" xyz="0 0 0"/>
      <geometry>
        <mesh filename="package://sample_hexapod_robot/meshes/LeftFrontLInk2.STL"/>
      </geometry>
      <material name="">
        <color rgba="1 1 1 1"/>
      </material>
    </visual>
    <collision>
      <origin rpy="0 0 0" xyz="0 0 0"/>
      <geometry>
        <mesh filename="package://sample_hexapod_robot/meshes/LeftFrontLInk2.STL"/>
      </geometry>
    </collision>
  </link>
  <joint name="LeftFrontJoint2" type="continuous">
    <origin rpy="1.5707963267949 -0.786246680508058 1.5707963267949" xyz="0 0.0269911968874116 -0.0186293668612354"/>
    <parent link="LeftFrontLink1"/>
    <child link="LeftFrontLInk2"/>
    <axis xyz="0 0 1"/>
    <dynamics damping="0.01"/>
  </joint>
  <link name="LeftFrontLink3">
    <inertial>
      <origin rpy="0 0 0" xyz="-0.00369426510069479 0.00543050677483787 -0.0404133474431356"/>
      <mass value="0.0123870986027426"/>
      <inertia ixx="1e-6" ixy="0" ixz="0" iyy="1e-6" iyz="0" izz="1e-6"/>
    </inertial>
    <visual>
      <origin rpy="0 0 0" xyz="0 0 0"/>
      <geometry>
        <mesh filename="package://sample_hexapod_robot/meshes/LeftFrontLink3.STL"/>
      </geometry>
      <material name="">
        <color rgba="0.698039215686274 0.698039215686274 0.698039215686274 1"/>
      </material>
    </visual>
    <collision>
      <origin rpy="0 0 0" xyz="0 0 0"/>
      <geometry>
        <mesh filename="package://sample_hexapod_robot/meshes/LeftFrontLink3.STL"/>
      </geometry>
    </collision>
  </link>
  <joint name="LeftFrontJoint3" type="continuous">
    <origin rpy="3.14159265358979 -0.785398163397443 1.5707963267949" xyz="0 -0.0284734 -0.0185936999519958"/>
    <parent link="LeftFrontLInk2"/>
    <child link="LeftFrontLink3"/>
    <axis xyz="0 1 0"/>
    <dynamics damping="0.01"/>
  </joint>
  <link name="LeftFrontLink4">
    <inertial>
      <origin rpy="0 0 0" xyz="0.0173312004836655 -0.00213695685902054 -0.00049907986087272"/>
      <mass value="0.0328903409487069"/>
      <inertia ixx="1e-6" ixy="0" ixz="0" iyy="1e-6" iyz="0" izz="1e-6"/>
    </inertial>
    <visual>
      <origin rpy="0 0 0" xyz="0 0 0"/>
      <geometry>
        <mesh filename="package://sample_hexapod_robot/meshes/LeftFrontLink4.STL"/>
      </geometry>
      <material name="">
        <color rgba="1 1 1 1"/>
      </material>
    </visual>
    <collision>
      <origin rpy="0 0 0" xyz="0 0 0"/>
      <geometry>
        <mesh filename="package://sample_hexapod_robot/meshes/LeftFrontLink4.STL"/>
      </geometry>
    </collision>
  </link>
  <joint name="LeftFrontJoint4" type="continuous">
    <origin rpy="1.5707963267959 -0.785398163398452 3.14159265358838" xyz="-0.0186563000000022 0 -0.073063099999997"/>
    <parent link="LeftFrontLink3"/>
    <child link="LeftFrontLink4"/>
    <axis xyz="0 0 1"/>
    <dynamics damping="0.01"/>
  </joint>
  <link name="MiddleRightLink1">
    <inertial>
      <origin rpy="0 0 0" xyz="-0.00338972796446857 0.0229454122748954 9.48742289353863E-07"/>
      <mass value="0.00662740565244451"/>
      <inertia ixx="1e-6" ixy="0" ixz="0" iyy="1e-6" iyz="0" izz="1e-6"/>
    </inertial>
    <visual>
      <origin rpy="0 0 0" xyz="0 0 0"/>
      <geometry>
        <mesh filename="package://sample_hexapod_robot/meshes/MiddleRightLink1.STL"/>
      </geometry>
      <material name="">
        <color rgba="0.752941176470588 0.752941176470588 0.752941176470588 1"/>
      </material>
    </visual>
    <collision>
      <origin rpy="0 0 0" xyz="0 0 0"/>
      <geometry>
        <mesh filename="package://sample_hexapod_robot/meshes/MiddleRightLink1.STL"/>
      </geometry>
    </collision>
  </link>
  <joint name="MiddleRightJoint1" type="fixed">
    <origin rpy="3.1416 1.5708 0" xyz="-0.0045313 -0.019413 -0.039989"/>
    <parent link="base_link"/>
    <child link="MiddleRightLink1"/>
    <axis xyz="0 0 0"/>
  </joint>
  <link name="MiddleRightLink2">
    <inertial>
      <origin rpy="0 0 0" xyz="0.00600434318283062 -0.0142239999999997 -0.00612161228746982"/>
      <mass value="0.0522696869799877"/>
      <inertia ixx="1e-6" ixy="0" ixz="0" iyy="1e-6" iyz="0" izz="1e-6"/>
    </inertial>
    <visual>
      <origin rpy="0 0 0" xyz="0 0 0"/>
      <geometry>
        <mesh filename="package://sample_hexapod_robot/meshes/MiddleRightLink2.STL"/>
      </geometry>
      <material name="">
        <color rgba="1 1 1 1"/>
      </material>
    </visual>
    <collision>
      <origin rpy="0 0 0" xyz="0 0 0"/>
      <geometry>
        <mesh filename="package://sample_hexapod_robot/meshes/MiddleRightLink2.STL"/>
      </geometry>
    </collision>
  </link>
  <joint name="MiddleRightJoint2" type="continuous">
    <origin rpy="3.1416 1.5708 0" xyz="0 0.046063 0"/>
    <parent link="MiddleRightLink1"/>
    <child link="MiddleRightLink2"/>
    <axis xyz="0 0 1"/>
    <dynamics damping="0.01"/>
  </joint>
  <link name="MiddleRightLink3">
    <inertial>
      <origin rpy="0 0 0" xyz="0.00369060677483836 -0.0404128398424318 0.00369375749998502"/>
      <mass value="0.0123870986027426"/>
      <inertia ixx="1e-6" ixy="0" ixz="0" iyy="1e-6" iyz="0" izz="1e-6"/>
    </inertial>
    <visual>
      <origin rpy="0 0 0" xyz="0 0 0"/>
      <geometry>
        <mesh filename="package://sample_hexapod_robot/meshes/MiddleRightLink3.STL"/>
      </geometry>
      <material name="">
        <color rgba="0.752941176470588 0.752941176470588 0.752941176470588 1"/>
      </material>
    </visual>
    <collision>
      <origin rpy="0 0 0" xyz="0 0 0"/>
      <geometry>
        <mesh filename="package://sample_hexapod_robot/meshes/MiddleRightLink3.STL"/>
      </geometry>
    </collision>
  </link>
  <joint name="MiddleRightJoint3" type="continuous">
    <origin rpy="-2.3562 0 -3.1416" xyz="0 -0.028448 -0.019114"/>
    <parent link="MiddleRightLink2"/>
    <child link="MiddleRightLink3"/>
    <axis xyz="1 0 0"/>
    <dynamics damping="0.01"/>
  </joint>
  <link name="MiddleRightLink4">
    <inertial>
      <origin rpy="0 0 0" xyz="0.0175022240505962 0.00213695685903806 -0.0022389798194285"/>
      <mass value="0.0328903409487069"/>
      <inertia ixx="1e-6" ixy="0" ixz="0" iyy="1e-6" iyz="0" izz="1e-6"/>
    </inertial>
    <visual>
      <origin rpy="0 0 0" xyz="0 0 0"/>
      <geometry>
        <mesh filename="package://sample_hexapod_robot/meshes/MiddleRightLink4.STL"/>
      </geometry>
      <material name="">
        <color rgba="1 1 1 1"/>
      </material>
    </visual>
    <collision>
      <origin rpy="0 0 0" xyz="0 0 0"/>
      <geometry>
        <mesh filename="package://sample_hexapod_robot/meshes/MiddleRightLink4.STL"/>
      </geometry>
    </collision>
  </link>
  <joint name="MiddleRightJoint4" type="continuous">
    <origin rpy="1.5708 -0.7854 1.5708" xyz="0 -0.073063 0.018656"/>
    <parent link="MiddleRightLink3"/>
    <child link="MiddleRightLink4"/>
    <axis xyz="0 0 1"/>
    <dynamics damping="0.01"/>
  </joint>
  <link name="MiddleLeftLink1">
    <inertial>
      <origin rpy="0 0 0" xyz="-0.00338972796446862 0.0229454122748954 -9.48742289343454E-07"/>
      <mass value="0.0066274056524445"/>
      <inertia ixx="1e-6" ixy="0" ixz="0" iyy="1e-6" iyz="0" izz="1e-6"/>
    </inertial>
    <visual>
      <origin rpy="0 0 0" xyz="0 0 0"/>
      <geometry>
        <mesh filename="package://sample_hexapod_robot/meshes/MiddleLeftLink1.STL"/>
      </geometry>
      <material name="">
        <color rgba="0.752941176470588 0.752941176470588 0.752941176470588 1"/>
      </material>
    </visual>
    <collision>
      <origin rpy="0 0 0" xyz="0 0 0"/>
      <geometry>
        <mesh filename="package://sample_hexapod_robot/meshes/MiddleLeftLink1.STL"/>
      </geometry>
    </collision>
  </link>
  <joint name="MiddleLeftJoint1" type="fixed">
    <origin rpy="0 1.5708 0" xyz="-0.0045313 0.032911 -0.039989"/>
    <parent link="base_link"/>
    <child link="MiddleLeftLink1"/>
    <axis xyz="0 0 0"/>
  </joint>
  <link name="MiddleLeftLink2">
    <inertial>
      <origin rpy="0 0 0" xyz="0.00630971916442873 0.0142240000000001 -0.00589358826906994"/>
      <mass value="0.0522696869799877"/>
      <inertia ixx="1e-6" ixy="0" ixz="0" iyy="1e-6" iyz="0" izz="1e-6"/>
    </inertial>
    <visual>
      <origin rpy="0 0 0" xyz="0 0 0"/>
      <geometry>
        <mesh filename="package://sample_hexapod_robot/meshes/MiddleLeftLink2.STL"/>
      </geometry>
      <material name="">
        <color rgba="1 1 1 1"/>
      </material>
    </visual>
    <collision>
      <origin rpy="0 0 0" xyz="0 0 0"/>
      <geometry>
        <mesh filename="package://sample_hexapod_robot/meshes/MiddleLeftLink2.STL"/>
      </geometry>
    </collision>
  </link>
  <joint name="MiddleLeftJoint2" type="continuous">
    <origin rpy="3.1416 -1.5708 3.14" xyz="0 0.046063 0"/>
    <parent link="MiddleLeftLink1"/>
    <child link="MiddleLeftLink2"/>
    <axis xyz="0 0 1"/>
    <dynamics damping="0.01"/>
  </joint>
  <link name="MiddleLeftLink3">
    <inertial>
      <origin rpy="0 0 0" xyz="0.00315720677483883 -0.0404138550438462 -0.00369375749998499"/>
      <mass value="0.0123870986027426"/>
      <inertia ixx="1e-6" ixy="0" ixz="0" iyy="1e-6" iyz="0" izz="1e-6"/>
    </inertial>
    <visual>
      <origin rpy="0 0 0" xyz="0 0 0"/>
      <geometry>
        <mesh filename="package://sample_hexapod_robot/meshes/MiddleLeftLink3.STL"/>
      </geometry>
      <material name="">
        <color rgba="0.752941176470588 0.752941176470588 0.752941176470588 1"/>
      </material>
    </visual>
    <collision>
      <origin rpy="0 0 0" xyz="0 0 0"/>
      <geometry>
        <mesh filename="package://sample_hexapod_robot/meshes/MiddleLeftLink3.STL"/>
      </geometry>
    </collision>
  </link>
  <joint name="MiddleLeftJoint3" type="continuous">
    <origin rpy="-0.7854 0 -3.1416" xyz="0 0.028448 -0.018581"/>
    <parent link="MiddleLeftLink2"/>
    <child link="MiddleLeftLink3"/>
    <axis xyz="1 0 0"/>
    <dynamics damping="0.01"/>
  </joint>
  <link name="MiddleLeftLink4">
    <inertial>
      <origin rpy="0 0 0" xyz="0.0173312004836624 -0.002136956859038 -0.00277237986085704"/>
      <mass value="0.0328903409487069"/>
      <inertia ixx="1e-6" ixy="0" ixz="0" iyy="1e-6" iyz="0" izz="1e-6"/>
    </inertial>
    <visual>
      <origin rpy="0 0 0" xyz="0 0 0"/>
      <geometry>
        <mesh filename="package://sample_hexapod_robot/meshes/MiddleLeftLink4.STL"/>
      </geometry>
      <material name="">
        <color rgba="1 1 1 1"/>
      </material>
    </visual>
    <collision>
      <origin rpy="0 0 0" xyz="0 0 0"/>
      <geometry>
        <mesh filename="package://sample_hexapod_robot/meshes/MiddleLeftLink4.STL"/>
      </geometry>
    </collision>
  </link>
  <joint name="MiddleLeftJoint4" type="continuous">
    <origin rpy="1.5708 0.7854 1.5708" xyz="0 -0.073063 -0.018656"/>
    <parent link="MiddleLeftLink3"/>
    <child link="MiddleLeftLink4"/>
    <axis xyz="0 0 1"/>
    <dynamics damping="0.01"/>
  </joint>
  <link name="BottomRightLink1">
    <inertial>
      <origin rpy="0 0 0" xyz="-0.00544490603885191 -0.0151146056014377 0.00266986656589765"/>
      <mass value="0.00840681165634204"/>
      <inertia ixx="1e-6" ixy="0" ixz="0" iyy="1e-6" iyz="0" izz="1e-6"/>
    </inertial>
    <visual>
      <origin rpy="0 0 0" xyz="0 0 0"/>
      <geometry>
        <mesh filename="package://sample_hexapod_robot/meshes/BottomRightLink1.STL"/>
      </geometry>
      <material name="">
        <color rgba="0.792156862745098 0.819607843137255 0.933333333333333 1"/>
      </material>
    </visual>
    <collision>
      <origin rpy="0 0 0" xyz="0 0 0"/>
      <geometry>
        <mesh filename="package://sample_hexapod_robot/meshes/BottomRightLink1.STL"/>
      </geometry>
    </collision>
  </link>
  <joint name="BottomRightJoint1" type="fixed">
    <origin rpy="0 0.00017514 0" xyz="-0.088859 -0.019413 -0.039989"/>
    <parent link="base_link"/>
    <child link="BottomRightLink1"/>
    <axis xyz="0 1 0"/>
  </joint>
  <link name="BottomRightLink2">
    <inertial>
      <origin rpy="0 0 0" xyz="0.00600434318283 -0.014224 -0.00613431228747037"/>
      <mass value="0.0522696869799878"/>
      <inertia ixx="1e-6" ixy="0" ixz="0" iyy="1e-6" iyz="0" izz="1e-6"/>
    </inertial>
    <visual>
      <origin rpy="0 0 0" xyz="0 0 0"/>
      <geometry>
        <mesh filename="package://sample_hexapod_robot/meshes/BottomRightLink2.STL"/>
      </geometry>
      <material name="">
        <color rgba="1 1 1 1"/>
      </material>
    </visual>
    <collision>
      <origin rpy="0 0 0" xyz="0 0 0"/>
      <geometry>
        <mesh filename="package://sample_hexapod_robot/meshes/BottomRightLink2.STL"/>
      </geometry>
    </collision>
  </link>
  <joint name="BottomRightJoint2" type="continuous">
    <origin rpy="0.00012374 -0.00012395 -0.78455" xyz="-0.018656 -0.03335 0"/>
    <parent link="BottomRightLink1"/>
    <child link="BottomRightLink2"/>
    <axis xyz="0 0 1"/>
    <dynamics damping="0.01"/>
  </joint>
  <link name="BottomRightLink3">
    <inertial>
      <origin rpy="0 0 0" xyz="-0.0404138550438458 0.00369060677483947 -0.00369375749998468"/>
      <mass value="0.0123870986027426"/>
      <inertia ixx="1e-6" ixy="0" ixz="0" iyy="1e-6" iyz="0" izz="1e-6"/>
    </inertial>
    <visual>
      <origin rpy="0 0 0" xyz="0 0 0"/>
      <geometry>
        <mesh filename="package://sample_hexapod_robot/meshes/BottomRightLink3.STL"/>
      </geometry>
      <material name="">
        <color rgba="0.698039215686274 0.698039215686274 0.698039215686274 1"/>
      </material>
    </visual>
    <collision>
      <origin rpy="0 0 0" xyz="0 0 0"/>
      <geometry>
        <mesh filename="package://sample_hexapod_robot/meshes/BottomRightLink3.STL"/>
      </geometry>
    </collision>
  </link>
  <joint name="BottomRightJoint3" type="continuous">
    <origin rpy="0 0.785398163397454 1.5707963267949" xyz="0 -0.028448 -0.019127099952"/>
    <parent link="BottomRightLink2"/>
    <child link="BottomRightLink3"/>
    <axis xyz="0 1 0"/>
    <dynamics damping="0.01"/>
  </joint>
  <link name="BottomRightLink4">
    <inertial>
      <origin rpy="0 0 0" xyz="0.017502222237589 0.00213695685903822 -0.00223898052686797"/>
      <mass value="0.0328903409487069"/>
      <inertia ixx="1e-6" ixy="0" ixz="0" iyy="1e-6" iyz="0" izz="1e-6"/>
    </inertial>
    <visual>
      <origin rpy="0 0 0" xyz="0 0 0"/>
      <geometry>
        <mesh filename="package://sample_hexapod_robot/meshes/BottomRightLink4.STL"/>
      </geometry>
      <material name="">
        <color rgba="1 1 1 1"/>
      </material>
    </visual>
    <collision>
      <origin rpy="0 0 0" xyz="0 0 0"/>
      <geometry>
        <mesh filename="package://sample_hexapod_robot/meshes/BottomRightLink4.STL"/>
      </geometry>
    </collision>
  </link>
  <joint name="BottomRightJoint4" type="continuous">
    <origin rpy="-1.5707963267949 0.785398163397442 0" xyz="-0.0730630999999976 0 -0.0186562999999977"/>
    <parent link="BottomRightLink3"/>
    <child link="BottomRightLink4"/>
    <axis xyz="0 0 1"/>
    <dynamics damping="0.01"/>
  </joint>
  <link name="BottomLeftLink1">
    <inertial>
      <origin rpy="0 0 0" xyz="-0.0054444383569754 -0.0151146056014377 -0.0026708198202042"/>
      <mass value="0.00840681165634204"/>
      <inertia ixx="1e-6" ixy="0" ixz="0" iyy="1e-6" iyz="0" izz="1e-6"/>
    </inertial>
    <visual>
      <origin rpy="0 0 0" xyz="0 0 0"/>
      <geometry>
        <mesh filename="package://sample_hexapod_robot/meshes/BottomLeftLink1.STL"/>
      </geometry>
      <material name="">
        <color rgba="0.792156862745098 0.819607843137255 0.933333333333333 1"/>
      </material>
    </visual>
    <collision>
      <origin rpy="0 0 0" xyz="0 0 0"/>
      <geometry>
        <mesh filename="package://sample_hexapod_robot/meshes/BottomLeftLink1.STL"/>
      </geometry>
    </collision>
  </link>
  <joint name="BottomLeftJoint1" type="fixed">
    <origin rpy="3.1416 0 0" xyz="-0.088859 0.032911 -0.039989"/>
    <parent link="base_link"/>
    <child link="BottomLeftLink1"/>
    <axis xyz="0 1 0"/>
  </joint>
  <link name="BottomLeftLink2">
    <inertial>
      <origin rpy="0 0 0" xyz="0.0213846191644279 0.0191261999999996 -0.00590628826906894"/>
      <mass value="0.0522696869799878"/>
      <inertia ixx="1e-6" ixy="0" ixz="0" iyy="1e-6" iyz="0" izz="1e-6"/>
    </inertial>
    <visual>
      <origin rpy="0 0 0" xyz="0 0 0"/>
      <geometry>
        <mesh filename="package://sample_hexapod_robot/meshes/BottomLeftLink2.STL"/>
      </geometry>
      <material name="">
        <color rgba="1 1 1 1"/>
      </material>
    </visual>
    <collision>
      <origin rpy="0 0 0" xyz="0 0 0"/>
      <geometry>
        <mesh filename="package://sample_hexapod_robot/meshes/BottomLeftLink2.STL"/>
      </geometry>
    </collision>
  </link>
  <joint name="BottomLeftJoint2" type="continuous">
    <origin rpy="3.14159265358979 0 -0.78454964628684" xyz="-0.0258614686662949 -0.0192303657467149 0"/>
    <parent link="BottomLeftLink1"/>
    <child link="BottomLeftLink2"/>
    <axis xyz="0 0 1"/>
    <dynamics damping="0.01"/>
  </joint>
  <link name="BottomLeftLink3">
    <inertial>
      <origin rpy="0 0 0" xyz="-0.0404138550438461 -0.0119176932251596 0.00369375749998496"/>
      <mass value="0.0123870986027426"/>
      <inertia ixx="1e-6" ixy="0" ixz="0" iyy="1e-6" iyz="0" izz="1e-6"/>
    </inertial>
    <visual>
      <origin rpy="0 0 0" xyz="0 0 0"/>
      <geometry>
        <mesh filename="package://sample_hexapod_robot/meshes/BottomLeftLink3.STL"/>
      </geometry>
      <material name="">
        <color rgba="0.698039215686274 0.698039215686274 0.698039215686274 1"/>
      </material>
    </visual>
    <collision>
      <origin rpy="0 0 0" xyz="0 0 0"/>
      <geometry>
        <mesh filename="package://sample_hexapod_robot/meshes/BottomLeftLink3.STL"/>
      </geometry>
    </collision>
  </link>
  <joint name="BottomLeftJoint3" type="continuous">
    <origin rpy="3.14159265358979 0.785398163397447 -1.5707963267949" xyz="0 0.0333501999999997 -0.0185936999519997"/>
    <parent link="BottomLeftLink2"/>
    <child link="BottomLeftLink3"/>
    <axis xyz="0 1 0"/>
    <dynamics damping="0.01"/>
  </joint>
  <link name="BottomLeftLink4">
    <inertial>
      <origin rpy="0 0 0" xyz="0.0173312022966688 -0.00213695685860177 -0.0178472805268687"/>
      <mass value="0.0328903409487069"/>
      <inertia ixx="1e-6" ixy="0" ixz="0" iyy="1e-6" iyz="0" izz="1e-6"/>
    </inertial>
    <visual>
      <origin rpy="0 0 0" xyz="0 0 0"/>
      <geometry>
        <mesh filename="package://sample_hexapod_robot/meshes/BottomLeftLink4.STL"/>
      </geometry>
      <material name="">
        <color rgba="1 1 1 1"/>
      </material>
    </visual>
    <collision>
      <origin rpy="0 0 0" xyz="0 0 0"/>
      <geometry>
        <mesh filename="package://sample_hexapod_robot/meshes/BottomLeftLink4.STL"/>
      </geometry>
    </collision>
  </link>
  <joint name="BottomLeftJoint4" type="continuous">
    <origin rpy="-1.57079632679503 -0.785398163397583 0" xyz="-0.0730630999999995 0 0.0186563000000002"/>
    <parent link="BottomLeftLink3"/>
    <child link="BottomLeftLink4"/>
    <axis xyz="0 0 1"/>
    <dynamics damping="0.01"/>
  </joint>

  <!-- FrontRightTransmissions -->
  <transmission name="RightFrontTran2">
    <type>transmission_interface/SimpleTransmission</type>
    <joint name="RightFrontJoint2">
      <hardwareInterface>hardware_interface/EffortJointInterface</hardwareInterface>
    </joint>
    <actuator name="RightFrontMotor2">
      <hardwareInterface>hardware_interface/EffortJointInterface</hardwareInterface>
      <mechanicalReduction>1</mechanicalReduction>
    </actuator>
  </transmission>
  <transmission name="RightFrontTran3">
    <type>transmission_interface/SimpleTransmission</type>
    <joint name="RightFrontJoint3">
      <hardwareInterface>hardware_interface/EffortJointInterface</hardwareInterface>
    </joint>
    <actuator name="RightFrontMotor3">
      <hardwareInterface>hardware_interface/EffortJointInterface</hardwareInterface>
      <mechanicalReduction>1</mechanicalReduction>
    </actuator>
  </transmission>
  <transmission name="RightFrontTran4">
    <type>transmission_interface/SimpleTransmission</type>
    <joint name="RightFrontJoint4">
      <hardwareInterface>hardware_interface/EffortJointInterface</hardwareInterface>
    </joint>
    <actuator name="RightFrontMotor4">
      <hardwareInterface>hardware_interface/EffortJointInterface</hardwareInterface>
      <mechanicalReduction>1</mechanicalReduction>
    </actuator>
  </transmission>


  <!-- LeftFrontTransmittion -->
  <transmission name="LeftFrontTran2">
    <type>transmission_interface/SimpleTransmission</type>
    <joint name="LeftFrontJoint2">
      <hardwareInterface>hardware_interface/EffortJointInterface</hardwareInterface>
    </joint>
    <actuator name="LeftFrontMotor2">
      <hardwareInterface>hardware_interface/EffortJointInterface</hardwareInterface>
      <mechanicalReduction>1</mechanicalReduction>
    </actuator>
  </transmission>
  <transmission name="LeftFrontTran3">
    <type>transmission_interface/SimpleTransmission</type>
    <joint name="LeftFrontJoint3">
      <hardwareInterface>hardware_interface/EffortJointInterface</hardwareInterface>
    </joint>
    <actuator name="LeftFrontMotor3">
      <hardwareInterface>hardware_interface/EffortJointInterface</hardwareInterface>
      <mechanicalReduction>1</mechanicalReduction>
    </actuator>
  </transmission>
  <transmission name="LeftFrontTran4">
    <type>transmission_interface/SimpleTransmission</type>
    <joint name="LeftFrontJoint4">
      <hardwareInterface>hardware_interface/EffortJointInterface</hardwareInterface>
    </joint>
    <actuator name="LeftFrontMotor4">
      <hardwareInterface>hardware_interface/EffortJointInterface</hardwareInterface>
      <mechanicalReduction>1</mechanicalReduction>
    </actuator>
  </transmission>

  <!-- MiddleRightTransmittion -->
  <transmission name="MiddleRightTran2">
    <type>transmission_interface/SimpleTransmission</type>
    <joint name="MiddleRightJoint2">
      <hardwareInterface>hardware_interface/EffortJointInterface</hardwareInterface>
    </joint>
    <actuator name="MiddleRightMotor2">
      <hardwareInterface>hardware_interface/EffortJointInterface</hardwareInterface>
      <mechanicalReduction>1</mechanicalReduction>
    </actuator>
  </transmission>
  <transmission name="MiddleRightTran3">
    <type>transmission_interface/SimpleTransmission</type>
    <joint name="MiddleRightJoint3">
      <hardwareInterface>hardware_interface/EffortJointInterface</hardwareInterface>
    </joint>
    <actuator name="MiddleRightMotor3">
      <hardwareInterface>hardware_interface/EffortJointInterface</hardwareInterface>
      <mechanicalReduction>1</mechanicalReduction>
    </actuator>
  </transmission>
  <transmission name="MiddleRightTran4">
    <type>transmission_interface/SimpleTransmission</type>
    <joint name="MiddleRightJoint4">
      <hardwareInterface>hardware_interface/EffortJointInterface</hardwareInterface>
    </joint>
    <actuator name="MiddleRightMotor4">
      <hardwareInterface>hardware_interface/EffortJointInterface</hardwareInterface>
      <mechanicalReduction>1</mechanicalReduction>
    </actuator>
  </transmission>

  <!-- MiddleLeftTransmittion -->
  <transmission name="MiddleLeftTran2">
    <type>transmission_interface/SimpleTransmission</type>
    <joint name="MiddleLeftJoint2">
      <hardwareInterface>hardware_interface/EffortJointInterface</hardwareInterface>
    </joint>
    <actuator name="MiddleLeftMotor2">
      <hardwareInterface>hardware_interface/EffortJointInterface</hardwareInterface>
      <mechanicalReduction>1</mechanicalReduction>
    </actuator>
  </transmission>
  <transmission name="MiddleLeftTran3">
    <type>transmission_interface/SimpleTransmission</type>
    <joint name="MiddleLeftJoint3">
      <hardwareInterface>hardware_interface/EffortJointInterface</hardwareInterface>
    </joint>
    <actuator name="MiddleLeftMotor3">
      <hardwareInterface>hardware_interface/EffortJointInterface</hardwareInterface>
      <mechanicalReduction>1</mechanicalReduction>
    </actuator>
  </transmission>
  <transmission name="MiddleLeftTran4">
    <type>transmission_interface/SimpleTransmission</type>
    <joint name="MiddleLeftJoint4">
      <hardwareInterface>hardware_interface/EffortJointInterface</hardwareInterface>
    </joint>
    <actuator name="MiddleLeftMotor4">
      <hardwareInterface>hardware_interface/EffortJointInterface</hardwareInterface>
      <mechanicalReduction>1</mechanicalReduction>
    </actuator>
  </transmission>

  <!-- BottomRightTransmittion -->
  <transmission name="BottomRightTran2">
    <type>transmission_interface/SimpleTransmission</type>
    <joint name="BottomRightJoint2">
      <hardwareInterface>hardware_interface/EffortJointInterface</hardwareInterface>
    </joint>
    <actuator name="BottomRightMotor2">
      <hardwareInterface>hardware_interface/EffortJointInterface</hardwareInterface>
      <mechanicalReduction>1</mechanicalReduction>
    </actuator>
  </transmission>
  <transmission name="BottomRightTran3">
    <type>transmission_interface/SimpleTransmission</type>
    <joint name="BottomRightJoint3">
      <hardwareInterface>hardware_interface/EffortJointInterface</hardwareInterface>
    </joint>
    <actuator name="BottomRightMotor3">
      <hardwareInterface>hardware_interface/EffortJointInterface</hardwareInterface>
      <mechanicalReduction>1</mechanicalReduction>
    </actuator>
  </transmission>
  <transmission name="BottomRightTran4">
    <type>transmission_interface/SimpleTransmission</type>
    <joint name="BottomRightJoint4">
      <hardwareInterface>hardware_interface/EffortJointInterface</hardwareInterface>
    </joint>
    <actuator name="BottomRightMotor4">
      <hardwareInterface>hardware_interface/EffortJointInterface</hardwareInterface>
      <mechanicalReduction>1</mechanicalReduction>
    </actuator>
  </transmission>

  <!-- BottomLeftTransmittion -->
  <transmission name="BottomLeftTran2">
    <type>transmission_interface/SimpleTransmission</type>
    <joint name="BottomLeftJoint2">
      <hardwareInterface>hardware_interface/EffortJointInterface</hardwareInterface>
    </joint>
    <actuator name="BottomLeftMotor2">
      <hardwareInterface>hardware_interface/EffortJointInterface</hardwareInterface>
      <mechanicalReduction>1</mechanicalReduction>
    </actuator>
  </transmission>
  <transmission name="BottomLeftTran3">
    <type>transmission_interface/SimpleTransmission</type>
    <joint name="BottomLeftJoint3">
      <hardwareInterface>hardware_interface/EffortJointInterface</hardwareInterface>
    </joint>
    <actuator name="BottomLeftMotor3">
      <hardwareInterface>hardware_interface/EffortJointInterface</hardwareInterface>
      <mechanicalReduction>1</mechanicalReduction>
    </actuator>
  </transmission>
  <transmission name="BottomLeftTran4">
    <type>transmission_interface/SimpleTransmission</type>
    <joint name="BottomLeftJoint4">
      <hardwareInterface>hardware_interface/EffortJointInterface</hardwareInterface>
    </joint>
    <actuator name="BottomLeftMotor4">
      <hardwareInterface>hardware_interface/EffortJointInterface</hardwareInterface>
      <mechanicalReduction>1</mechanicalReduction>
    </actuator>
  </transmission>

  <!-- Gazebo plugin decleration -->
  <gazebo>
    <plugin filename="libgazebo_ros_control.so" name="gazebo_ros_control">
      <robotNamespace>/sample_hexapod_robot</robotNamespace>
    </plugin>
  </gazebo>
</robot>
